<?xml version="1.0"?>
<sdf version='1.6'>
  <world name='default'>
    <light name='sun' type='directional'>
      <cast_shadows>1</cast_shadows>
      <pose frame=''>0 0 10 0 -0 0</pose>
      <diffuse>0.8 0.8 0.8 1</diffuse>
      <specular>0.2 0.2 0.2 1</specular>
      <attenuation>
        <range>1000</range>
        <constant>0.9</constant>
        <linear>0.01</linear>
        <quadratic>0.001</quadratic>
      </attenuation>
      <direction>-0.5 0.1 -0.9</direction>
    </light>
    <model name='ground_plane'>
      <static>1</static>
      <link name='link'>
        <collision name='collision'>
          <geometry>
            <plane>
              <normal>0 0 1</normal>
              <size>10 10</size>
            </plane>
          </geometry>
          <surface>
            <contact>
              <collide_bitmask>65535</collide_bitmask>
              <ode/>
            </contact>
            <friction>
              <ode>
                <mu>100</mu>
                <mu2>50</mu2>
              </ode>
              <torsional>
                <ode/>
              </torsional>
            </friction>
            <bounce/>
          </surface>
          <max_contacts>10</max_contacts>
        </collision>
        <visual name='visual'>
          <cast_shadows>0</cast_shadows>
          <geometry>
            <plane>
              <normal>0 0 1</normal>
              <size>10 10</size>
            </plane>
          </geometry>
          <material>
            <script>
              <uri>file://media/materials/scripts/gazebo.material</uri>
              <name>Gazebo/Grass</name>
            </script>
          </material>
        </visual>
        <self_collide>0</self_collide>
        <kinematic>0</kinematic>
        <enable_wind>0</enable_wind>
      </link>
    </model>
    <gravity>0 0 -9.8</gravity>
    <magnetic_field>6e-06 2.3e-05 -4.2e-05</magnetic_field>
    <atmosphere type='adiabatic'/>
    <physics name='default_physics' default='0' type='ode'>
      <max_step_size>0.001</max_step_size>
      <real_time_factor>1</real_time_factor>
      <real_time_update_rate>1000</real_time_update_rate>
    </physics>
    <scene>
      <ambient>0.4 0.4 0.4 1</ambient>
      <background>0.7 0.7 0.7 1</background>
      <shadows>1</shadows>
    </scene>
    <spherical_coordinates>
      <surface_model>EARTH_WGS84</surface_model>
      <latitude_deg>0</latitude_deg>
      <longitude_deg>0</longitude_deg>
      <elevation>0</elevation>
      <heading_deg>0</heading_deg>
    </spherical_coordinates>
    <state world_name='default'>
      <sim_time>2846 285000000</sim_time>
      <real_time>2034 12771606</real_time>
      <wall_time>1603481943 980440917</wall_time>
      <iterations>1959069</iterations>
      <model name='basecamara'>
        <pose frame=''>1.29168 -0.997913 0.003969 1.57079 1.57079 -3.14159</pose>
        <scale>1 1 1</scale>
        <link name='link'>
          <pose frame=''>1.29168 -0.997913 0.003969 1.57079 1.57079 -3.14159</pose>
          <velocity>0 0 0 0 -0 0</velocity>
          <acceleration>0 0 0 0 -0 0</acceleration>
          <wrench>0 0 0 0 -0 0</wrench>
        </link>
      </model>
      <model name='bin'>
        <pose frame=''>0.6 0 0.034 1.5708 -0 0</pose>
        <scale>1 1 1</scale>
        <link name='link_00'>
          <pose frame=''>0.6 0 0.034 1.5708 -0 0</pose>
          <velocity>0 0 0 0 -0 0</velocity>
          <acceleration>0 0 0 0 -0 0</acceleration>
          <wrench>0 0 0 0 -0 0</wrench>
        </link>
      </model>
      <model name='bottlecola'>
        <pose frame=''>-0.111318 0.883593 0.819806 3.0977 0.00213 -2.97801</pose>
        <scale>1 1 1</scale>
        <link name='link_00'>
          <pose frame=''>-0.111318 0.883593 0.819806 3.0977 0.00213 -2.97801</pose>
          <velocity>0 0 0 0 -0 0</velocity>
          <acceleration>0 0 0 0 -0 0</acceleration>
          <wrench>0 0 0 0 -0 0</wrench>
        </link>
      </model>
      <model name='bottlecola_0'>
        <pose frame=''>-0.085354 0.917768 0.366374 1.5708 -0 0</pose>
        <scale>1 1 1</scale>
        <link name='link_00'>
          <pose frame=''>-0.085354 0.917768 0.366374 1.5708 -0 0</pose>
          <velocity>0 0 0 0 -0 0</velocity>
          <acceleration>0 0 0 0 -0 0</acceleration>
          <wrench>0 0 0 0 -0 0</wrench>
        </link>
      </model>
      <model name='estante'>
        <pose frame=''>0 1.1 0.629826 1.5708 -0 0</pose>
        <scale>1 1 1</scale>
        <link name='link'>
          <pose frame=''>0 1.1 0.629826 1.5708 -0 0</pose>
          <velocity>0 0 0 0 -0 0</velocity>
          <acceleration>0 0 0 0 -0 0</acceleration>
          <wrench>0 0 0 0 -0 0</wrench>
        </link>
      </model>
      <model name='estante_0'>
        <pose frame=''>-1.1 0 0.629826 1.5708 -0 1.5708</pose>
        <scale>1 1 1</scale>
        <link name='link'>
          <pose frame=''>-1.1 0 0.629826 1.5708 -0 1.5708</pose>
          <velocity>0 0 0 0 -0 0</velocity>
          <acceleration>0 0 0 0 -0 0</acceleration>
          <wrench>0 0 0 0 -0 0</wrench>
        </link>
      </model>
      <model name='ground_plane'>
        <pose frame=''>0 0 0 0 -0 0</pose>
        <scale>1 1 1</scale>
        <link name='link'>
          <pose frame=''>0 0 0 0 -0 0</pose>
          <velocity>0 0 0 0 -0 0</velocity>
          <acceleration>0 0 0 0 -0 0</acceleration>
          <wrench>0 0 0 0 -0 0</wrench>
        </link>
      </model>
      <model name='irb_140'>
        <pose frame=''>-1e-06 1e-06 1.8e-05 -0.000252 -2.3e-05 8e-06</pose>
        <scale>1 1 1</scale>
        <link name='base_link'>
          <pose frame=''>-1e-06 1e-06 1.8e-05 -0.000252 -2.3e-05 8e-06</pose>
          <velocity>0.000339 3.1e-05 -0.004454 0.069251 0.005768 -0.00255</velocity>
          <acceleration>1.13582 -6.48393 -6.53389 -1.06876 -0.16515 -1.13842</acceleration>
          <wrench>29.9402 -170.916 -172.233 0 -0 0</wrench>
        </link>
        <link name='left_ext'>
          <pose frame=''>0.046559 0.519551 0.66123 3.09436 1.17089 -1.62293</pose>
          <velocity>0.000462 -0.014101 0.011016 0.020093 -0.003237 -0.007824</velocity>
          <acceleration>-0.466648 -19.1434 10.7499 -3.05112 -1.07887 -0.938775</acceleration>
          <wrench>-0.046665 -1.91434 1.07499 0 -0 0</wrench>
        </link>
        <link name='left_finger'>
          <pose frame=''>0.046622 0.593253 0.630118 3.09433 1.17088 -1.62295</pose>
          <velocity>0.00113 -0.013105 0.012692 0.027027 -0.008421 -0.016237</velocity>
          <acceleration>0.987903 -17.7524 12.4822 2.07037 -1.43506 0.04024</acceleration>
          <wrench>0.09879 -1.77524 1.24822 0 -0 0</wrench>
        </link>
        <link name='left_int'>
          <pose frame=''>0.025788 0.530786 0.656946 3.09436 1.17089 -1.6229</pose>
          <velocity>5e-05 -0.014391 0.011223 0.017124 -0.003066 -0.024991</velocity>
          <acceleration>0.263248 -19.7387 10.5717 0.699079 1.39009 -1.87835</acceleration>
          <wrench>0.026325 -1.97387 1.05717 0 -0 0</wrench>
        </link>
        <link name='link_1'>
          <pose frame=''>4e-06 -3.1e-05 2.1e-05 -2.3e-05 0.000256 1.57001</pose>
          <velocity>-0.001216 0.011889 -0.005763 0.053801 0.005273 -0.000309</velocity>
          <acceleration>0.135827 -3.07405 -6.74597 2.59009 -1.39249 -1.55999</acceleration>
          <wrench>4.69418 -106.239 -233.141 0 -0 0</wrench>
        </link>
        <link name='link_2'>
          <pose frame=''>5.4e-05 0.07005 0.352001 -1.9e-05 -0.169741 1.56999</pose>
          <velocity>-0.00011 -0.003074 -0.001117 0.050322 0.004039 0.010293</velocity>
          <acceleration>1.62408 -16.3871 -5.74147 0.314704 0.695056 -2.39995</acceleration>
          <wrench>25.9691 -262.03 -91.806 0 -0 0</wrench>
        </link>
        <link name='link_3'>
          <pose frame=''>0.064998 0.00918 0.706829 -2e-05 -0.119738 1.57001</pose>
          <velocity>0.001737 -0.018247 -0.004551 0.046652 0.004768 0.000477</velocity>
          <acceleration>2.5685 -25.4773 -5.296 2.87923 -0.604458 0.5788</acceleration>
          <wrench>43.6113 -432.587 -89.9223 0 -0 0</wrench>
        </link>
        <link name='link_4'>
          <pose frame=''>0.000186 0.246519 0.735379 -2e-05 -0.119738 1.57001</pose>
          <velocity>0.001512 -0.01905 0.005416 0.047152 0.004685 0.000819</velocity>
          <acceleration>1.33074 -26.8247 9.526 1.21816 0.764599 2.50003</acceleration>
          <wrench>4.9767 -100.319 35.6253 0 -0 0</wrench>
        </link>
        <link name='link_5'>
          <pose frame=''>0.000296 0.386508 0.752222 -2.4e-05 0.40026 1.56999</pose>
          <velocity>0.001394 -0.019607 0.011928 0.04971 0.005387 0.001908</velocity>
          <acceleration>0.981911 -27.0291 13.3737 1.64896 -1.39861 -0.029927</acceleration>
          <wrench>0.298403 -8.21416 4.06428 0 -0 0</wrench>
        </link>
        <link name='link_6'>
          <pose frame=''>0.000345 0.446369 0.726895 0.019981 0.400205 1.57001</pose>
          <velocity>0.000899 -0.017312 0.014326 0.009144 0.002658 -0.002074</velocity>
          <acceleration>-0.078267 -23.5544 16.4297 0.046508 0.934864 1.29665</acceleration>
          <wrench>-0.012124 -3.64858 2.54497 0 -0 0</wrench>
        </link>
        <link name='right_ext'>
          <pose frame=''>-0.046992 0.520355 0.66295 3.09436 1.17089 -1.6229</pose>
          <velocity>0.00063 -0.014963 0.011925 0.019706 0.008337 0.001995</velocity>
          <acceleration>-0.673419 -20.9609 11.8248 -2.76823 -0.474129 2.30212</acceleration>
          <wrench>-0.067342 -2.09609 1.18248 0 -0 0</wrench>
        </link>
        <link name='right_finger'>
          <pose frame=''>-0.046932 0.594057 0.631839 3.09435 1.17088 -1.62292</pose>
          <velocity>0.000643 -0.013752 0.01343 0.025104 0.006914 0.005949</velocity>
          <acceleration>-0.78719 -19.3525 13.388 -0.759058 0.821466 1.42535</acceleration>
          <wrench>-0.078719 -1.93525 1.3388 0 -0 0</wrench>
        </link>
        <link name='right_int'>
          <pose frame=''>-0.026203 0.531234 0.657902 3.09435 1.17089 -1.62292</pose>
          <velocity>0.00069 -0.015617 0.011957 0.024561 0.006214 0.004487</velocity>
          <acceleration>-0.820574 -22.1886 12.2455 0.223918 -1.49462 0.891186</acceleration>
          <wrench>-0.082057 -2.21886 1.22455 0 -0 0</wrench>
        </link>
      </model>
      <model name='kinect1'>
        <pose frame=''>0.6 0 1.2 -3.14159 1.57079 0</pose>
        <scale>1 1 1</scale>
        <link name='link'>
          <pose frame=''>0.6 0 1.2 -3.14159 1.57079 0</pose>
          <velocity>0 0 0 0 -0 0</velocity>
          <acceleration>0 0 0 0 -0 0</acceleration>
          <wrench>0 0 0 0 -0 0</wrench>
        </link>
      </model>
      <model name='sugar'>
        <pose frame=''>0.014766 0.993306 0.790193 2.65073 1.49744 0.988166</pose>
        <scale>1 1 1</scale>
        <link name='link_00'>
          <pose frame=''>0.014766 0.993306 0.790193 2.65073 1.49744 0.988166</pose>
          <velocity>0 0 0 0 -0 0</velocity>
          <acceleration>-1e-06 -4.4e-05 -0 -5e-06 9e-06 2.6e-05</acceleration>
          <wrench>-1e-06 -4.4e-05 -0 0 -0 0</wrench>
        </link>
      </model>
      <model name='sugar_0'>
        <pose frame=''>0.009655 0.844584 0.352225 1.57881 -0.03866 -3.13557</pose>
        <scale>1 1 1</scale>
        <link name='link_00'>
          <pose frame=''>0.009655 0.844584 0.352225 1.57881 -0.03866 -3.13557</pose>
          <velocity>0 0 0 0 -0 0</velocity>
          <acceleration>0 -4.4e-05 -0 -1e-06 -0 9e-06</acceleration>
          <wrench>0 -4.4e-05 -0 0 -0 0</wrench>
        </link>
      </model>
      <model name='tomato'>
        <pose frame=''>0.021558 1.01827 0.775486 1.53447 1.35331 -0.207958</pose>
        <scale>1 1 1</scale>
        <link name='link_00'>
          <pose frame=''>0.021558 1.01827 0.775486 1.53447 1.35331 -0.207958</pose>
          <velocity>0 0 0 0 -0 0</velocity>
          <acceleration>0 -4.4e-05 -0 0 -0 3.7e-05</acceleration>
          <wrench>0 -4.4e-05 -0 0 -0 0</wrench>
        </link>
      </model>
      <model name='tomato_0'>
        <pose frame=''>0.118353 0.886665 0.241724 1.56002 0.412421 -3.07253</pose>
        <scale>1 1 1</scale>
        <link name='link_00'>
          <pose frame=''>0.118353 0.886665 0.241724 1.56002 0.412421 -3.07253</pose>
          <velocity>0 0 0 0 -0 0</velocity>
          <acceleration>3e-06 -4.5e-05 -0.002286 0.04865 0.770454 0.004337</acceleration>
          <wrench>3e-06 -4.5e-05 -0.002286 0 -0 0</wrench>
        </link>
      </model>
      <light name='sun'>
        <pose frame=''>0 0 10 0 -0 0</pose>
      </light>
    </state>
    <gui fullscreen='0'>
      <camera name='user_camera'>
        <pose frame=''>0.583174 0.877428 0.507714 0 0.339642 1.2202</pose>
        <view_controller>ortho</view_controller>
        <projection_type>orthographic</projection_type>
      </camera>
    </gui>
    <wind/>
    <model name='irb_140'>
      <link name='base_link'>
        <pose frame=''>0 0 0 0 -0 0</pose>
        <inertial>
          <pose frame=''>-0.082 0.0004 0.0599 0 -0 0</pose>
          <mass>26.36</mass>
          <inertia>
            <ixx>0.222</ixx>
            <ixy>0</ixy>
            <ixz>0.0156</ixz>
            <iyy>0.3553</iyy>
            <iyz>0.0017</iyz>
            <izz>0.5236</izz>
          </inertia>
        </inertial>
        <collision name='base_link_collision'>
          <pose frame=''>0 0 0 0 -0 0</pose>
          <geometry>
            <mesh>
              <scale>0.01 0.01 0.01</scale>
              <uri>/home/mateo/catkin_ws/src/abb_irb140_ros_sim/irb140_sim/meshes/irb140/collision_low_poly/base_link.stl</uri>
            </mesh>
          </geometry>
          <surface>
            <contact>
              <ode/>
            </contact>
            <friction>
              <ode/>
              <torsional>
                <ode/>
              </torsional>
            </friction>
            <bounce/>
          </surface>
          <max_contacts>10</max_contacts>
        </collision>
        <visual name='base_link_visual'>
          <pose frame=''>0 0 0 0 -0 0</pose>
          <geometry>
            <mesh>
              <scale>0.01 0.01 0.01</scale>
              <uri>/home/mateo/catkin_ws/src/abb_irb140_ros_sim/irb140_sim/meshes/irb140/visual/base_link.stl</uri>
            </mesh>
          </geometry>
          <material>
            <script>
              <name>Gazebo/Orange</name>
              <uri>file://media/materials/scripts/gazebo.material</uri>
            </script>
          </material>
        </visual>
        <gravity>1</gravity>
        <velocity_decay/>
        <self_collide>0</self_collide>
        <enable_wind>0</enable_wind>
        <kinematic>0</kinematic>
      </link>
      <joint name='fixed' type='fixed'>
        <child>base_link</child>
        <parent>world</parent>
      </joint>
      <link name='link_1'>
        <pose frame=''>0 0 0 0 -0 0</pose>
        <inertial>
          <pose frame=''>0.0281 0.0438 0.2634 0 -0 0</pose>
          <mass>34.56</mass>
          <inertia>
            <ixx>0.5087</ixx>
            <ixy>-0.0014</ixy>
            <ixz>-0.0524</ixz>
            <iyy>0.4612</iyy>
            <iyz>-0.0688</iyz>
            <izz>0.4567</izz>
          </inertia>
        </inertial>
        <collision name='link_1_collision'>
          <pose frame=''>0 0 0 0 -0 0</pose>
          <geometry>
            <mesh>
              <scale>0.01 0.01 0.01</scale>
              <uri>/home/mateo/catkin_ws/src/abb_irb140_ros_sim/irb140_sim/meshes/irb140/collision_low_poly/link_1.stl</uri>
            </mesh>
          </geometry>
          <surface>
            <contact>
              <ode/>
            </contact>
            <friction>
              <ode/>
              <torsional>
                <ode/>
              </torsional>
            </friction>
            <bounce/>
          </surface>
          <max_contacts>10</max_contacts>
        </collision>
        <visual name='link_1_visual'>
          <pose frame=''>0 0 0 0 -0 0</pose>
          <geometry>
            <mesh>
              <scale>0.01 0.01 0.01</scale>
              <uri>/home/mateo/catkin_ws/src/abb_irb140_ros_sim/irb140_sim/meshes/irb140/visual/link_1.stl</uri>
            </mesh>
          </geometry>
          <material>
            <script>
              <name>Gazebo/Orange</name>
              <uri>file://media/materials/scripts/gazebo.material</uri>
            </script>
          </material>
        </visual>
        <gravity>1</gravity>
        <velocity_decay/>
        <self_collide>0</self_collide>
        <enable_wind>0</enable_wind>
        <kinematic>0</kinematic>
      </link>
      <joint name='joint_1' type='revolute'>
        <child>link_1</child>
        <parent>base_link</parent>
        <axis>
          <xyz>0 0 1</xyz>
          <limit>
            <lower>-3.1416</lower>
            <upper>3.1416</upper>
            <effort>1000</effort>
            <velocity>2.618</velocity>
          </limit>
          <dynamics>
            <spring_reference>0</spring_reference>
            <spring_stiffness>0</spring_stiffness>
          </dynamics>
          <use_parent_model_frame>1</use_parent_model_frame>
        </axis>
      </joint>
      <link name='link_2'>
        <pose frame=''>0.07 0 0.352 0 -0 0</pose>
        <inertial>
          <pose frame=''>-0.0097 -0.0924 0.1983 0 -0 0</pose>
          <mass>15.99</mass>
          <inertia>
            <ixx>0.3286</ixx>
            <ixy>0.001</ixy>
            <ixz>-0.0038</ixz>
            <iyy>0.2775</iyy>
            <iyz>0.0379</iyz>
            <izz>0.0948</izz>
          </inertia>
        </inertial>
        <collision name='link_2_collision'>
          <pose frame=''>-0.07 0 -0.352 0 -0 0</pose>
          <geometry>
            <mesh>
              <scale>0.01 0.01 0.01</scale>
              <uri>/home/mateo/catkin_ws/src/abb_irb140_ros_sim/irb140_sim/meshes/irb140/collision_low_poly/link_2.stl</uri>
            </mesh>
          </geometry>
          <surface>
            <contact>
              <ode/>
            </contact>
            <friction>
              <ode/>
              <torsional>
                <ode/>
              </torsional>
            </friction>
            <bounce/>
          </surface>
          <max_contacts>10</max_contacts>
        </collision>
        <visual name='link_2_visual'>
          <pose frame=''>-0.07 0 -0.352 0 -0 0</pose>
          <geometry>
            <mesh>
              <scale>0.01 0.01 0.01</scale>
              <uri>/home/mateo/catkin_ws/src/abb_irb140_ros_sim/irb140_sim/meshes/irb140/visual/link_2.stl</uri>
            </mesh>
          </geometry>
          <material>
            <script>
              <name>Gazebo/Orange</name>
              <uri>file://media/materials/scripts/gazebo.material</uri>
            </script>
          </material>
        </visual>
        <gravity>1</gravity>
        <velocity_decay/>
        <self_collide>0</self_collide>
        <enable_wind>0</enable_wind>
        <kinematic>0</kinematic>
      </link>
      <joint name='joint_2' type='revolute'>
        <child>link_2</child>
        <parent>link_1</parent>
        <axis>
          <xyz>0 1 0</xyz>
          <limit>
            <lower>-1.7453</lower>
            <upper>1.7453</upper>
            <effort>1000</effort>
            <velocity>2.618</velocity>
          </limit>
          <dynamics>
            <spring_reference>0</spring_reference>
            <spring_stiffness>0</spring_stiffness>
          </dynamics>
          <use_parent_model_frame>1</use_parent_model_frame>
        </axis>
      </joint>
      <link name='link_3'>
        <pose frame=''>0.07 -0.065 0.712 0 -0 0</pose>
        <inertial>
          <pose frame=''>0.0196 0.0725 -0.0057 0 -0 0</pose>
          <mass>16.9793</mass>
          <inertia>
            <ixx>0.0682</ixx>
            <ixy>0.0063</ixy>
            <ixz>0.004</ixz>
            <iyy>0.199</iyy>
            <iyz>0.0007</iyz>
            <izz>0.1823</izz>
          </inertia>
        </inertial>
        <collision name='link_3_collision'>
          <pose frame=''>-0.07 0.065 -0.712 0 -0 0</pose>
          <geometry>
            <mesh>
              <scale>0.01 0.01 0.01</scale>
              <uri>/home/mateo/catkin_ws/src/abb_irb140_ros_sim/irb140_sim/meshes/irb140/collision_low_poly/link_3.stl</uri>
            </mesh>
          </geometry>
          <surface>
            <contact>
              <ode/>
            </contact>
            <friction>
              <ode/>
              <torsional>
                <ode/>
              </torsional>
            </friction>
            <bounce/>
          </surface>
          <max_contacts>10</max_contacts>
        </collision>
        <visual name='link_3_visual'>
          <pose frame=''>-0.07 0.065 -0.712 0 -0 0</pose>
          <geometry>
            <mesh>
              <scale>0.01 0.01 0.01</scale>
              <uri>/home/mateo/catkin_ws/src/abb_irb140_ros_sim/irb140_sim/meshes/irb140/visual/link_3.stl</uri>
            </mesh>
          </geometry>
          <material>
            <script>
              <name>Gazebo/Orange</name>
              <uri>file://media/materials/scripts/gazebo.material</uri>
            </script>
          </material>
        </visual>
        <gravity>1</gravity>
        <velocity_decay/>
        <self_collide>0</self_collide>
        <enable_wind>0</enable_wind>
        <kinematic>0</kinematic>
      </link>
      <joint name='joint_3' type='revolute'>
        <child>link_3</child>
        <parent>link_2</parent>
        <axis>
          <xyz>0 1 0</xyz>
          <limit>
            <lower>-2.4434</lower>
            <upper>2.4434</upper>
            <effort>1000</effort>
            <velocity>2.618</velocity>
          </limit>
          <dynamics>
            <spring_reference>0</spring_reference>
            <spring_stiffness>0</spring_stiffness>
          </dynamics>
          <use_parent_model_frame>1</use_parent_model_frame>
        </axis>
      </joint>
      <link name='link_4'>
        <pose frame=''>0.309 0 0.712 0 -0 0</pose>
        <inertial>
          <pose frame=''>0.0726 -0.0012 -0.0014 0 -0 0</pose>
          <mass>3.7398</mass>
          <inertia>
            <ixx>0.0073</ixx>
            <ixy>0.0004</ixy>
            <ixz>-0.0001</ixz>
            <iyy>0.0153</iyy>
            <iyz>0</iyz>
            <izz>0.0172</izz>
          </inertia>
        </inertial>
        <collision name='link_4_collision'>
          <pose frame=''>-0.309 0 -0.712 0 -0 0</pose>
          <geometry>
            <mesh>
              <scale>0.01 0.01 0.01</scale>
              <uri>/home/mateo/catkin_ws/src/abb_irb140_ros_sim/irb140_sim/meshes/irb140/collision_low_poly/link_4.stl</uri>
            </mesh>
          </geometry>
          <surface>
            <contact>
              <ode/>
            </contact>
            <friction>
              <ode/>
              <torsional>
                <ode/>
              </torsional>
            </friction>
            <bounce/>
          </surface>
          <max_contacts>10</max_contacts>
        </collision>
        <visual name='link_4_visual'>
          <pose frame=''>-0.309 0 -0.712 0 -0 0</pose>
          <geometry>
            <mesh>
              <scale>0.01 0.01 0.01</scale>
              <uri>/home/mateo/catkin_ws/src/abb_irb140_ros_sim/irb140_sim/meshes/irb140/visual/link_4.stl</uri>
            </mesh>
          </geometry>
          <material>
            <script>
              <name>Gazebo/Orange</name>
              <uri>file://media/materials/scripts/gazebo.material</uri>
            </script>
          </material>
        </visual>
        <visual name='link_4_fixed_joint_lump__cam_link_visual_1'>
          <pose frame=''>0 0 0.1 0 -0 0</pose>
          <geometry>
            <mesh>
              <scale>1 1 1</scale>
              <uri>/home/mateo/catkin_ws/src/abb_irb140_ros_sim/irb140_sim/meshes/kinect/meshes/kinect.dae</uri>
            </mesh>
          </geometry>
          <material>
            <script>
              <uri>__default__</uri>
              <name>__default__</name>
            </script>
          </material>
        </visual>
        <velocity_decay/>
        <gravity>1</gravity>
        <velocity_decay/>
        <sensor name='camera' type='depth'>
          <update_rate>20</update_rate>
          <camera name='__default__'>
            <horizontal_fov>1.0472</horizontal_fov>
            <image>
              <width>640</width>
              <height>480</height>
              <format>R8G8B8</format>
            </image>
            <clip>
              <near>0.05</near>
              <far>3</far>
            </clip>
          </camera>
          <plugin name='camera_plugin' filename='libgazebo_ros_openni_kinect.so'>
            <baseline>0.2</baseline>
            <alwaysOn>1</alwaysOn>
            <updateRate>0.0</updateRate>
            <cameraName>camera_ir</cameraName>
            <imageTopicName>/camera/color/image_raw</imageTopicName>
            <cameraInfoTopicName>/camera/color/camera_info</cameraInfoTopicName>
            <depthImageTopicName>/camera/depth/image_raw</depthImageTopicName>
            <depthImageCameraInfoTopicName>/camera/depth/camera_info</depthImageCameraInfoTopicName>
            <pointCloudTopicName>/camera/depth/points</pointCloudTopicName>
            <frameName>cam_depth_link</frameName>
            <pointCloudCutoff>0.5</pointCloudCutoff>
            <pointCloudCutoffMax>3.0</pointCloudCutoffMax>
            <distortionK1>0</distortionK1>
            <distortionK2>0</distortionK2>
            <distortionK3>0</distortionK3>
            <distortionT1>0</distortionT1>
            <distortionT2>0</distortionT2>
            <CxPrime>0</CxPrime>
            <Cx>0</Cx>
            <Cy>0</Cy>
            <focalLength>0</focalLength>
            <hackBaseline>0</hackBaseline>
            <robotNamespace>/</robotNamespace>
          </plugin>
          <pose frame=''>0 0 0.1 0 -0 0</pose>
        </sensor>
        <self_collide>0</self_collide>
        <enable_wind>0</enable_wind>
        <kinematic>0</kinematic>
      </link>
      <joint name='joint_4' type='revolute'>
        <child>link_4</child>
        <parent>link_3</parent>
        <axis>
          <xyz>1 0 0</xyz>
          <limit>
            <lower>-3.49</lower>
            <upper>3.49</upper>
            <effort>1000</effort>
            <velocity>6.2832</velocity>
          </limit>
          <dynamics>
            <spring_reference>0</spring_reference>
            <spring_stiffness>0</spring_stiffness>
          </dynamics>
          <use_parent_model_frame>1</use_parent_model_frame>
        </axis>
      </joint>
      <link name='link_5'>
        <pose frame=''>0.45 0 0.712 0 -0 0</pose>
        <inertial>
          <pose frame=''>-0.0014 0.0006 -0.0002 0 -0 0</pose>
          <mass>0.3039</mass>
          <inertia>
            <ixx>0.001</ixx>
            <ixy>0</ixy>
            <ixz>0</ixz>
            <iyy>0.002</iyy>
            <iyz>0</iyz>
            <izz>0.001</izz>
          </inertia>
        </inertial>
        <collision name='link_5_collision'>
          <pose frame=''>-0.45 0 -0.712 0 -0 0</pose>
          <geometry>
            <mesh>
              <scale>0.01 0.01 0.01</scale>
              <uri>/home/mateo/catkin_ws/src/abb_irb140_ros_sim/irb140_sim/meshes/irb140/collision_low_poly/link_5.stl</uri>
            </mesh>
          </geometry>
          <surface>
            <contact>
              <ode/>
            </contact>
            <friction>
              <ode/>
              <torsional>
                <ode/>
              </torsional>
            </friction>
            <bounce/>
          </surface>
          <max_contacts>10</max_contacts>
        </collision>
        <visual name='link_5_visual'>
          <pose frame=''>-0.45 0 -0.712 0 -0 0</pose>
          <geometry>
            <mesh>
              <scale>0.01 0.01 0.01</scale>
              <uri>/home/mateo/catkin_ws/src/abb_irb140_ros_sim/irb140_sim/meshes/irb140/visual/link_5.stl</uri>
            </mesh>
          </geometry>
          <material>
            <script>
              <name>Gazebo/Orange</name>
              <uri>file://media/materials/scripts/gazebo.material</uri>
            </script>
          </material>
        </visual>
        <gravity>1</gravity>
        <velocity_decay/>
        <self_collide>0</self_collide>
        <enable_wind>0</enable_wind>
        <kinematic>0</kinematic>
      </link>
      <joint name='joint_5' type='revolute'>
        <child>link_5</child>
        <parent>link_4</parent>
        <axis>
          <xyz>0 1 0</xyz>
          <limit>
            <lower>-2.0071</lower>
            <upper>2.0071</upper>
            <effort>1000</effort>
            <velocity>6.2832</velocity>
          </limit>
          <dynamics>
            <spring_reference>0</spring_reference>
            <spring_stiffness>0</spring_stiffness>
          </dynamics>
          <use_parent_model_frame>1</use_parent_model_frame>
        </axis>
      </joint>
      <link name='link_6'>
        <pose frame=''>0.515 0 0.712 0 -0 0</pose>
        <inertial>
          <pose frame=''>0.036064 0 0 0 -0 0</pose>
          <mass>0.1549</mass>
          <inertia>
            <ixx>0.699139</ixx>
            <ixy>0</ixy>
            <ixz>3.46598e-17</ixz>
            <iyy>0.898251</iyy>
            <iyz>0</iyz>
            <izz>0.133136</izz>
          </inertia>
        </inertial>
        <collision name='link_6_collision'>
          <pose frame=''>-0.515 0 -0.712 0 -0 0</pose>
          <geometry>
            <mesh>
              <scale>0.01 0.01 0.01</scale>
              <uri>/home/mateo/catkin_ws/src/abb_irb140_ros_sim/irb140_sim/meshes/irb140/collision_low_poly/link_6.stl</uri>
            </mesh>
          </geometry>
          <surface>
            <contact>
              <ode/>
            </contact>
            <friction>
              <ode/>
              <torsional>
                <ode/>
              </torsional>
            </friction>
            <bounce/>
          </surface>
          <max_contacts>10</max_contacts>
        </collision>
        <collision name='link_6_fixed_joint_lump__gripper_body_collision_1'>
          <pose frame=''>0 0 0 3.14159 1.57079 3.14159</pose>
          <geometry>
            <mesh>
              <scale>0.001 0.001 0.001</scale>
              <uri>/home/mateo/catkin_ws/src/abb_irb140_ros_sim/apc_gripper/meshes/mesh_soporte.stl</uri>
            </mesh>
          </geometry>
          <max_contacts>10</max_contacts>
          <surface>
            <contact>
              <ode/>
            </contact>
            <bounce/>
            <friction>
              <torsional>
                <ode/>
              </torsional>
              <ode/>
            </friction>
          </surface>
        </collision>
        <visual name='link_6_visual'>
          <pose frame=''>-0.515 0 -0.712 0 -0 0</pose>
          <geometry>
            <mesh>
              <scale>0.01 0.01 0.01</scale>
              <uri>/home/mateo/catkin_ws/src/abb_irb140_ros_sim/irb140_sim/meshes/irb140/visual/link_6.stl</uri>
            </mesh>
          </geometry>
          <material>
            <script>
              <name>Gazebo/Orange</name>
              <uri>file://media/materials/scripts/gazebo.material</uri>
            </script>
          </material>
        </visual>
        <visual name='link_6_fixed_joint_lump__gripper_body_visual_1'>
          <pose frame=''>0 0 0 3.14159 1.57079 3.14159</pose>
          <geometry>
            <mesh>
              <scale>0.001 0.001 0.001</scale>
              <uri>/home/mateo/catkin_ws/src/abb_irb140_ros_sim/apc_gripper/meshes/mesh_soporte.stl</uri>
            </mesh>
          </geometry>
        </visual>
        <gravity>1</gravity>
        <velocity_decay/>
        <self_collide>0</self_collide>
        <enable_wind>0</enable_wind>
        <kinematic>0</kinematic>
      </link>
      <joint name='joint_6' type='revolute'>
        <child>link_6</child>
        <parent>link_5</parent>
        <axis>
          <xyz>1 0 0</xyz>
          <limit>
            <lower>-6.9813</lower>
            <upper>6.9813</upper>
            <effort>1000</effort>
            <velocity>1</velocity>
          </limit>
          <dynamics>
            <spring_reference>0</spring_reference>
            <spring_stiffness>0</spring_stiffness>
          </dynamics>
          <use_parent_model_frame>1</use_parent_model_frame>
        </axis>
      </joint>
      <link name='left_ext'>
        <pose frame=''>0.608025 -0.046785 0.680974 0 1.57 0</pose>
        <inertial>
          <pose frame=''>-0.031 0 0.04 0 -0 0</pose>
          <mass>0.1</mass>
          <inertia>
            <ixx>2.13613e-05</ixx>
            <ixy>0</ixy>
            <ixz>0</ixz>
            <iyy>5.95838e-05</iyy>
            <iyz>0</iyz>
            <izz>3.94382e-05</izz>
          </inertia>
        </inertial>
        <collision name='left_ext_collision'>
          <pose frame=''>0 0 0 0 -0 0</pose>
          <geometry>
            <mesh>
              <scale>0.001 0.001 0.001</scale>
              <uri>/home/mateo/catkin_ws/src/abb_irb140_ros_sim/apc_gripper/meshes/mesh_eslabon.stl</uri>
            </mesh>
          </geometry>
          <max_contacts>10</max_contacts>
          <surface>
            <contact>
              <ode/>
            </contact>
            <bounce/>
            <friction>
              <torsional>
                <ode/>
              </torsional>
              <ode/>
            </friction>
          </surface>
        </collision>
        <visual name='left_ext_visual'>
          <pose frame=''>0 0 0 0 -0 0</pose>
          <geometry>
            <mesh>
              <scale>0.001 0.001 0.001</scale>
              <uri>/home/mateo/catkin_ws/src/abb_irb140_ros_sim/apc_gripper/meshes/mesh_eslabon.stl</uri>
            </mesh>
          </geometry>
        </visual>
        <self_collide>0</self_collide>
        <enable_wind>0</enable_wind>
        <kinematic>0</kinematic>
      </link>
      <joint name='gripper_body__left_ext' type='revolute'>
        <child>left_ext</child>
        <parent>link_6</parent>
        <axis>
          <xyz>0.000796 0 -1</xyz>
          <limit>
            <lower>-3.14</lower>
            <upper>3.14</upper>
            <effort>1000</effort>
            <velocity>0.5</velocity>
          </limit>
          <dynamics>
            <spring_reference>0</spring_reference>
            <spring_stiffness>0</spring_stiffness>
          </dynamics>
          <use_parent_model_frame>1</use_parent_model_frame>
        </axis>
      </joint>
      <link name='left_finger'>
        <pose frame=''>0.688025 -0.046785 0.681038 0 1.57 0</pose>
        <inertial>
          <pose frame=''>-0.031 0.018 0.032 0 -0 0</pose>
          <mass>0.1</mass>
          <inertia>
            <ixx>8.47702e-05</ixx>
            <ixy>0</ixy>
            <ixz>0</ixz>
            <iyy>9.5504e-05</iyy>
            <iyz>0</iyz>
            <izz>3.31406e-05</izz>
          </inertia>
        </inertial>
        <collision name='left_finger_collision'>
          <pose frame=''>0 0 0 0 -0 0</pose>
          <geometry>
            <mesh>
              <scale>0.001 0.001 0.001</scale>
              <uri>/home/mateo/catkin_ws/src/abb_irb140_ros_sim/apc_gripper/meshes/mesh_dedo.stl</uri>
            </mesh>
          </geometry>
          <max_contacts>10</max_contacts>
          <surface>
            <contact>
              <ode/>
            </contact>
            <bounce/>
            <friction>
              <torsional>
                <ode/>
              </torsional>
              <ode/>
            </friction>
          </surface>
        </collision>
        <visual name='left_finger_visual'>
          <pose frame=''>0 0 0 0 -0 0</pose>
          <geometry>
            <mesh>
              <scale>0.001 0.001 0.001</scale>
              <uri>/home/mateo/catkin_ws/src/abb_irb140_ros_sim/apc_gripper/meshes/mesh_dedo.stl</uri>
            </mesh>
          </geometry>
        </visual>
        <self_collide>0</self_collide>
        <enable_wind>0</enable_wind>
        <kinematic>0</kinematic>
      </link>
      <joint name='left_ext__left_finger' type='revolute'>
        <child>left_finger</child>
        <parent>left_ext</parent>
        <axis>
          <xyz>0.000796 0 -1</xyz>
          <limit>
            <lower>-3.14</lower>
            <upper>3.14</upper>
            <effort>1000</effort>
            <velocity>0.5</velocity>
          </limit>
          <dynamics>
            <spring_reference>0</spring_reference>
            <spring_stiffness>0</spring_stiffness>
          </dynamics>
          <use_parent_model_frame>1</use_parent_model_frame>
        </axis>
      </joint>
      <link name='left_int'>
        <pose frame=''>0.620025 -0.026 0.680984 0 1.57 0</pose>
        <inertial>
          <pose frame=''>-0.031 0 0.04 0 -0 0</pose>
          <mass>0.1</mass>
          <inertia>
            <ixx>2.13613e-05</ixx>
            <ixy>0</ixy>
            <ixz>0</ixz>
            <iyy>5.95838e-05</iyy>
            <iyz>0</iyz>
            <izz>3.94382e-05</izz>
          </inertia>
        </inertial>
        <collision name='left_int_collision'>
          <pose frame=''>0 0 0 0 -0 0</pose>
          <geometry>
            <mesh>
              <scale>0.001 0.001 0.001</scale>
              <uri>/home/mateo/catkin_ws/src/abb_irb140_ros_sim/apc_gripper/meshes/mesh_eslabon.stl</uri>
            </mesh>
          </geometry>
          <max_contacts>10</max_contacts>
          <surface>
            <contact>
              <ode/>
            </contact>
            <bounce/>
            <friction>
              <torsional>
                <ode/>
              </torsional>
              <ode/>
            </friction>
          </surface>
        </collision>
        <visual name='left_int_visual'>
          <pose frame=''>0 0 0 0 -0 0</pose>
          <geometry>
            <mesh>
              <scale>0.001 0.001 0.001</scale>
              <uri>/home/mateo/catkin_ws/src/abb_irb140_ros_sim/apc_gripper/meshes/mesh_eslabon.stl</uri>
            </mesh>
          </geometry>
        </visual>
        <self_collide>0</self_collide>
        <enable_wind>0</enable_wind>
        <kinematic>0</kinematic>
      </link>
      <joint name='gripper_body__left_int' type='revolute'>
        <child>left_int</child>
        <parent>link_6</parent>
        <axis>
          <xyz>0.000796 0 -1</xyz>
          <limit>
            <lower>-3.14</lower>
            <upper>3.14</upper>
            <effort>1000</effort>
            <velocity>0.5</velocity>
          </limit>
          <dynamics>
            <spring_reference>0</spring_reference>
            <spring_stiffness>0</spring_stiffness>
          </dynamics>
          <use_parent_model_frame>1</use_parent_model_frame>
        </axis>
      </joint>
      <link name='right_ext'>
        <pose frame=''>0.608025 0.046785 0.680974 0 1.57 0</pose>
        <inertial>
          <pose frame=''>-0.031 0 0.04 0 -0 0</pose>
          <mass>0.1</mass>
          <inertia>
            <ixx>2.13613e-05</ixx>
            <ixy>0</ixy>
            <ixz>0</ixz>
            <iyy>5.95838e-05</iyy>
            <iyz>0</iyz>
            <izz>3.94382e-05</izz>
          </inertia>
        </inertial>
        <collision name='right_ext_collision'>
          <pose frame=''>0 0 0 0 -0 0</pose>
          <geometry>
            <mesh>
              <scale>0.001 0.001 0.001</scale>
              <uri>/home/mateo/catkin_ws/src/abb_irb140_ros_sim/apc_gripper/meshes/mesh_eslabon.stl</uri>
            </mesh>
          </geometry>
          <max_contacts>10</max_contacts>
          <surface>
            <contact>
              <ode/>
            </contact>
            <bounce/>
            <friction>
              <torsional>
                <ode/>
              </torsional>
              <ode/>
            </friction>
          </surface>
        </collision>
        <visual name='right_ext_visual'>
          <pose frame=''>0 0 0 0 -0 0</pose>
          <geometry>
            <mesh>
              <scale>0.001 0.001 0.001</scale>
              <uri>/home/mateo/catkin_ws/src/abb_irb140_ros_sim/apc_gripper/meshes/mesh_eslabon.stl</uri>
            </mesh>
          </geometry>
        </visual>
        <self_collide>0</self_collide>
        <enable_wind>0</enable_wind>
        <kinematic>0</kinematic>
      </link>
      <joint name='gripper_body__right_ext' type='revolute'>
        <child>right_ext</child>
        <parent>link_6</parent>
        <axis>
          <xyz>0.000796 0 -1</xyz>
          <limit>
            <lower>-3.14</lower>
            <upper>3.14</upper>
            <effort>1000</effort>
            <velocity>0.5</velocity>
          </limit>
          <dynamics>
            <spring_reference>0</spring_reference>
            <spring_stiffness>0</spring_stiffness>
          </dynamics>
          <use_parent_model_frame>1</use_parent_model_frame>
        </axis>
      </joint>
      <link name='right_finger'>
        <pose frame=''>0.688025 0.046785 0.681038 0 1.57 0</pose>
        <inertial>
          <pose frame=''>-0.031 -0.018 0.032 0 -0 -3.14159</pose>
          <mass>0.1</mass>
          <inertia>
            <ixx>8.47702e-05</ixx>
            <ixy>0</ixy>
            <ixz>0</ixz>
            <iyy>9.5504e-05</iyy>
            <iyz>0</iyz>
            <izz>3.31406e-05</izz>
          </inertia>
        </inertial>
        <collision name='right_finger_collision'>
          <pose frame=''>-0.062 0 0 0 -0 -3.14159</pose>
          <geometry>
            <mesh>
              <scale>0.001 0.001 0.001</scale>
              <uri>/home/mateo/catkin_ws/src/abb_irb140_ros_sim/apc_gripper/meshes/mesh_dedo.stl</uri>
            </mesh>
          </geometry>
          <max_contacts>10</max_contacts>
          <surface>
            <contact>
              <ode/>
            </contact>
            <bounce/>
            <friction>
              <torsional>
                <ode/>
              </torsional>
              <ode/>
            </friction>
          </surface>
        </collision>
        <visual name='right_finger_visual'>
          <pose frame=''>-0.062 0 0 0 -0 -3.14159</pose>
          <geometry>
            <mesh>
              <scale>0.001 0.001 0.001</scale>
              <uri>/home/mateo/catkin_ws/src/abb_irb140_ros_sim/apc_gripper/meshes/mesh_dedo.stl</uri>
            </mesh>
          </geometry>
        </visual>
        <self_collide>0</self_collide>
        <enable_wind>0</enable_wind>
        <kinematic>0</kinematic>
      </link>
      <joint name='right_ext__right_finger' type='revolute'>
        <child>right_finger</child>
        <parent>right_ext</parent>
        <axis>
          <xyz>0.000796 0 -1</xyz>
          <limit>
            <lower>-3.14</lower>
            <upper>3.14</upper>
            <effort>1000</effort>
            <velocity>0.5</velocity>
          </limit>
          <dynamics>
            <spring_reference>0</spring_reference>
            <spring_stiffness>0</spring_stiffness>
          </dynamics>
          <use_parent_model_frame>1</use_parent_model_frame>
        </axis>
      </joint>
      <link name='right_int'>
        <pose frame=''>0.620025 0.026 0.680984 0 1.57 0</pose>
        <inertial>
          <pose frame=''>-0.031 0 0.04 0 -0 0</pose>
          <mass>0.1</mass>
          <inertia>
            <ixx>2.13613e-05</ixx>
            <ixy>0</ixy>
            <ixz>0</ixz>
            <iyy>5.95838e-05</iyy>
            <iyz>0</iyz>
            <izz>3.94382e-05</izz>
          </inertia>
        </inertial>
        <collision name='right_int_collision'>
          <pose frame=''>0 0 0 0 -0 0</pose>
          <geometry>
            <mesh>
              <scale>0.001 0.001 0.001</scale>
              <uri>/home/mateo/catkin_ws/src/abb_irb140_ros_sim/apc_gripper/meshes/mesh_eslabon.stl</uri>
            </mesh>
          </geometry>
          <max_contacts>10</max_contacts>
          <surface>
            <contact>
              <ode/>
            </contact>
            <bounce/>
            <friction>
              <torsional>
                <ode/>
              </torsional>
              <ode/>
            </friction>
          </surface>
        </collision>
        <visual name='right_int_visual'>
          <pose frame=''>0 0 0 0 -0 0</pose>
          <geometry>
            <mesh>
              <scale>0.001 0.001 0.001</scale>
              <uri>/home/mateo/catkin_ws/src/abb_irb140_ros_sim/apc_gripper/meshes/mesh_eslabon.stl</uri>
            </mesh>
          </geometry>
        </visual>
        <self_collide>0</self_collide>
        <enable_wind>0</enable_wind>
        <kinematic>0</kinematic>
      </link>
      <joint name='gripper_body__right_int' type='revolute'>
        <child>right_int</child>
        <parent>link_6</parent>
        <axis>
          <xyz>0.000796 0 -1</xyz>
          <limit>
            <lower>-3.14</lower>
            <upper>3.14</upper>
            <effort>1000</effort>
            <velocity>0.5</velocity>
          </limit>
          <dynamics>
            <spring_reference>0</spring_reference>
            <spring_stiffness>0</spring_stiffness>
          </dynamics>
          <use_parent_model_frame>1</use_parent_model_frame>
        </axis>
      </joint>
      <plugin name='gazebo_ros_control' filename='libgazebo_ros_control.so'>
        <robotNamespace>/irb_140</robotNamespace>
        <robotSimType>gazebo_ros_control/DefaultRobotHWSim</robotSimType>
      </plugin>
      <static>0</static>
      <joint name='left_int__left_finger' type='revolute'>
        <parent>left_int</parent>
        <child>left_finger</child>
        <pose frame=''>0 0.020785 0.012 -3.14159 -0 0</pose>
        <axis>
          <xyz>1 0 0</xyz>
          <use_parent_model_frame>1</use_parent_model_frame>
          <limit>
            <lower>-1e+16</lower>
            <upper>1e+16</upper>
          </limit>
          <dynamics>
            <spring_reference>0</spring_reference>
            <spring_stiffness>0</spring_stiffness>
          </dynamics>
        </axis>
      </joint>
      <joint name='right_int__right_finger' type='revolute'>
        <parent>right_int</parent>
        <child>right_finger</child>
        <pose frame=''>0 -0.020785 0.012 0 -0 0</pose>
        <axis>
          <xyz>1 0 0</xyz>
          <limit>
            <lower>-3.14</lower>
            <upper>3.14</upper>
            <effort>1000</effort>
            <velocity>0.5</velocity>
          </limit>
          <use_parent_model_frame>1</use_parent_model_frame>
          <dynamics>
            <spring_reference>0</spring_reference>
            <spring_stiffness>0</spring_stiffness>
          </dynamics>
        </axis>
      </joint>
      <pose frame=''>0 0 0 0 -0 0</pose>
    </model>
    <model name='estante'>
      <pose frame=''>0.218682 0.914944 0.725 1.5708 -0 0</pose>
      <link name='link'>
        <visual name='visual'>
          <pose frame=''>0 0 0 1.5708 -0 0</pose>
          <material>
            <script>
              <uri>file://media/materials/scripts/gazebo.material</uri>
              <name>Gazebo/Wood</name>
            </script>
          </material>
          <geometry>
            <mesh>
              <uri>model://estante/estante2.dae</uri>
            </mesh>
          </geometry>
        </visual>
        <collision name='collision'>
          <pose frame=''>0 0 0 1.5708 -0 0</pose>
          <max_contacts>10</max_contacts>
          <geometry>
            <mesh>
              <uri>model://estante/estante2.dae</uri>
            </mesh>
          </geometry>
          <surface>
            <friction>
              <ode>
                <mu>50</mu>
                <mu2>100</mu2>
                <fdir1>0 0 0</fdir1>
                <slip1>1</slip1>
                <slip2>1</slip2>
              </ode>
              <torsional>
                <ode/>
              </torsional>
            </friction>
            <contact>
              <ode>
                <max_vel>0.01</max_vel>
                <min_depth>0.001</min_depth>
              </ode>
            </contact>
            <bounce/>
          </surface>
        </collision>
        <inertial>
          <mass>76.26</mass>
          <inertia>
            <ixx>47</ixx>
            <ixy>-0.003456</ixy>
            <ixz>0.001474</ixz>
            <izz>13.075</izz>
            <iyz>-0.014439</iyz>
            <iyy>47</iyy>
          </inertia>
        </inertial>
        <self_collide>0</self_collide>
        <enable_wind>0</enable_wind>
        <kinematic>0</kinematic>
      </link>
      <static>1</static>
    </model>
    <model name='estante_0'>
      <pose frame=''>-0.756626 0.062813 0.725 1.5708 -0 0</pose>
      <link name='link'>
        <visual name='visual'>
          <pose frame=''>0 0 0 1.5708 -0 0</pose>
          <material>
            <script>
              <uri>file://media/materials/scripts/gazebo.material</uri>
              <name>Gazebo/Wood</name>
            </script>
          </material>
          <geometry>
            <mesh>
              <uri>model://estante/estante2.dae</uri>
            </mesh>
          </geometry>
        </visual>
        <collision name='collision'>
          <pose frame=''>0 0 0 1.5708 -0 0</pose>
          <max_contacts>10</max_contacts>
          <geometry>
            <mesh>
              <uri>model://estante/estante2.dae</uri>
            </mesh>
          </geometry>
          <surface>
            <friction>
              <ode>
                <mu>50</mu>
                <mu2>100</mu2>
                <fdir1>0 0 0</fdir1>
                <slip1>1</slip1>
                <slip2>1</slip2>
              </ode>
              <torsional>
                <ode/>
              </torsional>
            </friction>
            <contact>
              <ode>
                <max_vel>0.01</max_vel>
                <min_depth>0.001</min_depth>
              </ode>
            </contact>
            <bounce/>
          </surface>
        </collision>
        <inertial>
          <mass>76.26</mass>
          <inertia>
            <ixx>47</ixx>
            <ixy>-0.003456</ixy>
            <ixz>0.001474</ixz>
            <izz>13.075</izz>
            <iyz>-0.014439</iyz>
            <iyy>47</iyy>
          </inertia>
        </inertial>
        <self_collide>0</self_collide>
        <enable_wind>0</enable_wind>
        <kinematic>0</kinematic>
      </link>
      <static>1</static>
    </model>
    <model name='bin'>
      <pose frame=''>1.73434 -0.662811 1 0 -0 0</pose>
      <static>1</static>
      <link name='link_00'>
        <pose frame=''>0 0 0 0 -0 0</pose>
        <visual name='visual_00'>
          <geometry>
            <mesh>
              <uri>model://bin/binv1.dae</uri>
            </mesh>
          </geometry>
          <material>
            <script>
              <name>Gazebo/Orange</name>
              <uri>file://media/materials/scripts/gazebo.material</uri>
            </script>
          </material>
        </visual>
        <collision name='collision'>
          <geometry>
            <mesh>
              <uri>model://bin/binc1.dae</uri>
            </mesh>
          </geometry>
          <surface>
            <friction>
              <ode>
                <mu>50</mu>
                <mu2>100</mu2>
                <fdir1>0 0 0</fdir1>
                <slip1>1</slip1>
                <slip2>1</slip2>
              </ode>
              <torsional>
                <ode/>
              </torsional>
            </friction>
            <contact>
              <ode>
                <max_vel>0.001</max_vel>
                <min_depth>0.0001</min_depth>
              </ode>
            </contact>
            <bounce/>
          </surface>
          <max_contacts>10</max_contacts>
        </collision>
        <inertial>
          <mass>10</mass>
          <pose frame=''>-0.01 0.004 0.017 0 -0 0</pose>
          <inertia>
            <ixx>0.001</ixx>
            <ixy>0</ixy>
            <ixz>-0</ixz>
            <iyy>0.001</iyy>
            <iyz>0</iyz>
            <izz>0.001</izz>
          </inertia>
        </inertial>
        <self_collide>0</self_collide>
        <enable_wind>0</enable_wind>
        <kinematic>0</kinematic>
      </link>
    </model>
    <model name='kinect1'>
      <pose frame=''>0.647555 -0.604894 0.036 0 0.52 1.5708</pose>
      <static>1</static>
      <link name='link'>
        <inertial>
          <mass>0.1</mass>
        </inertial>
        <collision name='collision'>
          <geometry>
            <box>
              <size>0.073 0.276 0.072</size>
            </box>
          </geometry>
          <max_contacts>10</max_contacts>
          <surface>
            <contact>
              <ode/>
            </contact>
            <bounce/>
            <friction>
              <torsional>
                <ode/>
              </torsional>
              <ode/>
            </friction>
          </surface>
        </collision>
        <visual name='visual'>
          <geometry>
            <mesh>
              <uri>model://kinect1/meshes/kinect.dae</uri>
            </mesh>
          </geometry>
        </visual>
        <sensor name='camera' type='depth'>
          <update_rate>20</update_rate>
          <camera name='__default__'>
            <horizontal_fov>1.0472</horizontal_fov>
            <image>
              <width>640</width>
              <height>480</height>
              <format>R8G8B8</format>
            </image>
            <clip>
              <near>0.05</near>
              <far>3</far>
            </clip>
          </camera>
          <plugin name='camera_plugin' filename='libgazebo_ros_openni_kinect.so'>
            <baseline>0.2</baseline>
            <alwaysOn>1</alwaysOn>
            <updateRate>0.0</updateRate>
            <cameraName>camera_ir1</cameraName>
            <imageTopicName>/camera/color/image_raw1</imageTopicName>
            <cameraInfoTopicName>/camera/color/camera_info1</cameraInfoTopicName>
            <depthImageTopicName>/camera/depth/image_raw1</depthImageTopicName>
            <depthImageCameraInfoTopicName>/camera/depth/camera_info1</depthImageCameraInfoTopicName>
            <pointCloudTopicName>/camera/depth/points1</pointCloudTopicName>
            <frameName>camera_link1</frameName>
            <pointCloudCutoff>0.5</pointCloudCutoff>
            <pointCloudCutoffMax>3.0</pointCloudCutoffMax>
            <distortionK1>0</distortionK1>
            <distortionK2>0</distortionK2>
            <distortionK3>0</distortionK3>
            <distortionT1>0</distortionT1>
            <distortionT2>0</distortionT2>
            <CxPrime>0</CxPrime>
            <Cx>0</Cx>
            <Cy>0</Cy>
            <focalLength>0</focalLength>
            <hackBaseline>0</hackBaseline>
          </plugin>
        </sensor>
        <self_collide>0</self_collide>
        <enable_wind>0</enable_wind>
        <kinematic>0</kinematic>
      </link>
    </model>
    <model name='basecamara'>
      <pose frame=''>1.80765 -1.25851 1 1.57079 1.57079 -3.14159</pose>
      <link name='link'>
        <visual name='visual'>
          <pose frame=''>0 0 1 1.57079 1.57079 3.14159</pose>
          <material>
            <script>
              <uri>file://media/materials/scripts/gazebo.material</uri>
              <name>Gazebo/Grey</name>
            </script>
          </material>
          <geometry>
            <mesh>
              <uri>model://basecamara/basecamara.dae</uri>
            </mesh>
          </geometry>
        </visual>
        <collision name='collision'>
          <pose frame=''>0 0 1 1.57079 1.57079 3.14159</pose>
          <max_contacts>10</max_contacts>
          <geometry>
            <mesh>
              <uri>model://basecamara/basecamara.dae</uri>
            </mesh>
          </geometry>
          <surface>
            <friction>
              <ode>
                <mu>50</mu>
                <mu2>100</mu2>
                <fdir1>0 0 0</fdir1>
                <slip1>1</slip1>
                <slip2>1</slip2>
              </ode>
              <torsional>
                <ode/>
              </torsional>
            </friction>
            <contact>
              <ode>
                <max_vel>0.01</max_vel>
                <min_depth>0.001</min_depth>
              </ode>
            </contact>
            <bounce/>
          </surface>
        </collision>
        <inertial>
          <mass>76.26</mass>
          <inertia>
            <ixx>47</ixx>
            <ixy>-0.003456</ixy>
            <ixz>0.001474</ixz>
            <izz>13.075</izz>
            <iyz>-0.014439</iyz>
            <iyy>47</iyy>
          </inertia>
        </inertial>
        <self_collide>0</self_collide>
        <enable_wind>0</enable_wind>
        <kinematic>0</kinematic>
      </link>
      <static>1</static>
    </model>
    <model name='bottlecola'>
      <pose frame=''>-0.247252 0.746499 1 0 -0 0</pose>
      <static>1</static>
      <link name='link_00'>
        <pose frame=''>0 0 0 0 -0 0</pose>
        <visual name='visual_00'>
          <geometry>
            <mesh>
              <uri>model://bottlecola/bottlecola.dae</uri>
            </mesh>
          </geometry>
          <material>
            <script>
              <name>Gazebo/Black</name>
              <uri>file://media/materials/scripts/gazebo.material</uri>
            </script>
          </material>
        </visual>
        <collision name='collision'>
          <geometry>
            <mesh>
              <uri>model://bottlecola/bottlecola.dae</uri>
            </mesh>
          </geometry>
          <surface>
            <friction>
              <ode>
                <mu>50</mu>
                <mu2>100</mu2>
                <fdir1>0 0 0</fdir1>
                <slip1>1</slip1>
                <slip2>1</slip2>
              </ode>
              <torsional>
                <ode/>
              </torsional>
            </friction>
            <contact>
              <ode>
                <max_vel>0.001</max_vel>
                <min_depth>0.0001</min_depth>
              </ode>
            </contact>
            <bounce/>
          </surface>
          <max_contacts>10</max_contacts>
        </collision>
        <inertial>
          <mass>10</mass>
          <pose frame=''>-0.01 0.004 0.017 0 -0 0</pose>
          <inertia>
            <ixx>0.001</ixx>
            <ixy>0</ixy>
            <ixz>-0</ixz>
            <iyy>0.001</iyy>
            <iyz>0</iyz>
            <izz>0.001</izz>
          </inertia>
        </inertial>
        <self_collide>0</self_collide>
        <enable_wind>0</enable_wind>
        <kinematic>0</kinematic>
      </link>
    </model>
    <model name='tomato'>
      <pose frame=''>-0.494675 2.36215 0.1 0 -0 0</pose>
      <link name='link_00'>
        <pose frame=''>0 0 0 0 -0 0</pose>
        <visual name='visual_00'>
          <geometry>
            <mesh>
              <uri>model://tomato/textured.dae</uri>
            </mesh>
          </geometry>
        </visual>
        <collision name='collision'>
          <geometry>
            <mesh>
              <uri>model://tomato/collision.dae</uri>
            </mesh>
          </geometry>
          <surface>
            <friction>
              <ode>
                <mu>50</mu>
                <mu2>100</mu2>
                <fdir1>0 0 0</fdir1>
                <slip1>1</slip1>
                <slip2>1</slip2>
              </ode>
              <torsional>
                <ode/>
              </torsional>
            </friction>
            <contact>
              <ode>
                <max_vel>0.001</max_vel>
                <min_depth>0.0001</min_depth>
              </ode>
            </contact>
            <bounce/>
          </surface>
          <max_contacts>10</max_contacts>
        </collision>
        <inertial>
          <pose frame=''>-0.009 0.084 0.05 0 -0 0</pose>
          <inertia>
            <ixx>3e-05</ixx>
            <ixy>0</ixy>
            <ixz>0</ixz>
            <iyy>3e-05</iyy>
            <iyz>-0</iyz>
            <izz>2e-05</izz>
          </inertia>
          <mass>1</mass>
        </inertial>
        <self_collide>0</self_collide>
        <enable_wind>0</enable_wind>
        <kinematic>0</kinematic>
      </link>
    </model>
    <model name='sugar'>
      <pose frame=''>-0.467578 2.82369 0.1 0 -0 0</pose>
      <link name='link_00'>
        <pose frame=''>0 0 0 0 -0 0</pose>
        <visual name='visual_00'>
          <geometry>
            <mesh>
              <uri>model://sugar/textured.dae</uri>
            </mesh>
          </geometry>
        </visual>
        <collision name='collision'>
          <geometry>
            <mesh>
              <uri>model://sugar/collision.dae</uri>
            </mesh>
          </geometry>
          <surface>
            <friction>
              <ode>
                <mu>50</mu>
                <mu2>100</mu2>
                <fdir1>0 0 0</fdir1>
                <slip1>1</slip1>
                <slip2>1</slip2>
              </ode>
              <torsional>
                <ode/>
              </torsional>
            </friction>
            <contact>
              <ode>
                <max_vel>0.1</max_vel>
                <min_depth>0.001</min_depth>
              </ode>
            </contact>
            <bounce/>
          </surface>
          <max_contacts>10</max_contacts>
        </collision>
        <inertial>
          <pose frame=''>-0.008 -0.017 0.086 0 -0 0</pose>
          <inertia>
            <ixx>0.0002</ixx>
            <ixy>0</ixy>
            <ixz>-1e-05</ixz>
            <iyy>0.00017</iyy>
            <iyz>0</iyz>
            <izz>5e-05</izz>
          </inertia>
          <mass>1</mass>
        </inertial>
        <self_collide>0</self_collide>
        <enable_wind>0</enable_wind>
        <kinematic>0</kinematic>
      </link>
    </model>
    <model name='tomato_0'>
      <pose frame=''>-0.403074 1.81505 0.1 0 -0 0</pose>
      <link name='link_00'>
        <pose frame=''>0 0 0 0 -0 0</pose>
        <visual name='visual_00'>
          <geometry>
            <mesh>
              <uri>model://tomato/textured.dae</uri>
            </mesh>
          </geometry>
        </visual>
        <collision name='collision'>
          <geometry>
            <mesh>
              <uri>model://tomato/collision.dae</uri>
            </mesh>
          </geometry>
          <surface>
            <friction>
              <ode>
                <mu>50</mu>
                <mu2>100</mu2>
                <fdir1>0 0 0</fdir1>
                <slip1>1</slip1>
                <slip2>1</slip2>
              </ode>
              <torsional>
                <ode/>
              </torsional>
            </friction>
            <contact>
              <ode>
                <max_vel>0.001</max_vel>
                <min_depth>0.0001</min_depth>
              </ode>
            </contact>
            <bounce/>
          </surface>
          <max_contacts>10</max_contacts>
        </collision>
        <inertial>
          <pose frame=''>-0.009 0.084 0.05 0 -0 0</pose>
          <inertia>
            <ixx>3e-05</ixx>
            <ixy>0</ixy>
            <ixz>0</ixz>
            <iyy>3e-05</iyy>
            <iyz>-0</iyz>
            <izz>2e-05</izz>
          </inertia>
          <mass>1</mass>
        </inertial>
        <self_collide>0</self_collide>
        <enable_wind>0</enable_wind>
        <kinematic>0</kinematic>
      </link>
    </model>
    <model name='sugar_0'>
      <pose frame=''>-0.076251 1.89726 0.1 0 -0 0</pose>
      <link name='link_00'>
        <pose frame=''>0 0 0 0 -0 0</pose>
        <visual name='visual_00'>
          <geometry>
            <mesh>
              <uri>model://sugar/textured.dae</uri>
            </mesh>
          </geometry>
        </visual>
        <collision name='collision'>
          <geometry>
            <mesh>
              <uri>model://sugar/collision.dae</uri>
            </mesh>
          </geometry>
          <surface>
            <friction>
              <ode>
                <mu>50</mu>
                <mu2>100</mu2>
                <fdir1>0 0 0</fdir1>
                <slip1>1</slip1>
                <slip2>1</slip2>
              </ode>
              <torsional>
                <ode/>
              </torsional>
            </friction>
            <contact>
              <ode>
                <max_vel>0.1</max_vel>
                <min_depth>0.001</min_depth>
              </ode>
            </contact>
            <bounce/>
          </surface>
          <max_contacts>10</max_contacts>
        </collision>
        <inertial>
          <pose frame=''>-0.008 -0.017 0.086 0 -0 0</pose>
          <inertia>
            <ixx>0.0002</ixx>
            <ixy>0</ixy>
            <ixz>-1e-05</ixz>
            <iyy>0.00017</iyy>
            <iyz>0</iyz>
            <izz>5e-05</izz>
          </inertia>
          <mass>1</mass>
        </inertial>
        <self_collide>0</self_collide>
        <enable_wind>0</enable_wind>
        <kinematic>0</kinematic>
      </link>
    </model>
    <model name='bottlecola_0'>
      <pose frame=''>-0.398448 2.05774 1 0 -0 0</pose>
      <static>1</static>
      <link name='link_00'>
        <pose frame=''>0 0 0 0 -0 0</pose>
        <visual name='visual_00'>
          <geometry>
            <mesh>
              <uri>model://bottlecola/bottlecola.dae</uri>
            </mesh>
          </geometry>
          <material>
            <script>
              <name>Gazebo/Black</name>
              <uri>file://media/materials/scripts/gazebo.material</uri>
            </script>
          </material>
        </visual>
        <collision name='collision'>
          <geometry>
            <mesh>
              <uri>model://bottlecola/bottlecola.dae</uri>
            </mesh>
          </geometry>
          <surface>
            <friction>
              <ode>
                <mu>50</mu>
                <mu2>100</mu2>
                <fdir1>0 0 0</fdir1>
                <slip1>1</slip1>
                <slip2>1</slip2>
              </ode>
              <torsional>
                <ode/>
              </torsional>
            </friction>
            <contact>
              <ode>
                <max_vel>0.001</max_vel>
                <min_depth>0.0001</min_depth>
              </ode>
            </contact>
            <bounce/>
          </surface>
          <max_contacts>10</max_contacts>
        </collision>
        <inertial>
          <mass>10</mass>
          <pose frame=''>-0.01 0.004 0.017 0 -0 0</pose>
          <inertia>
            <ixx>0.001</ixx>
            <ixy>0</ixy>
            <ixz>-0</ixz>
            <iyy>0.001</iyy>
            <iyz>0</iyz>
            <izz>0.001</izz>
          </inertia>
        </inertial>
        <self_collide>0</self_collide>
        <enable_wind>0</enable_wind>
        <kinematic>0</kinematic>
      </link>
    </model>
  </world>
</sdf>
