<?xml version="1.0" ?>

<robot xmlns:xacro="http://ros.org/wiki/xacro">
  
  <!-- LINKS_BASE JOINTS -->

    <joint name="gripper_body__left_ext" type="prismatic">
      <axis xyz="0 1 0" />
      <limit effort="1000" lower="-0.1" upper="0.1" velocity="0.5" />
      <origin rpy="0 0 0" xyz="0.0311 -0.046785 0.093" />
      <parent link="gripper_body" />
      <child link="left_ext" />
    </joint>
    <transmission name="trans_gripper_body__left_ext">
      <type>transmission_interface/SimpleTransmission</type>
      <joint name="gripper_body__left_ext">
        <hardwareInterface>hardware_interface/PositionJointInterface</hardwareInterface>
      </joint>
      <actuator name="motor_gripper_body__left_ext">
        <hardwareInterface>hardware_interface/PositionJointInterface</hardwareInterface>
        <mechanicalReduction>1</mechanicalReduction>
      </actuator>
    </transmission>

    <joint name="gripper_body__right_ext" type="prismatic">
      <axis xyz="0 1 0" />
      <limit effort="1000" lower="-0.1" upper="0.1" velocity="0.5" />
      <origin rpy="0 0 0" xyz="0.0311 0.046785 0.093" />
      <parent link="gripper_body" />
      <child link="right_ext" />
    </joint>
    <transmission name="trans_gripper_body__right_ext">
      <type>transmission_interface/SimpleTransmission</type>
      <joint name="gripper_body__right_ext">
        <hardwareInterface>hardware_interface/PositionJointInterface</hardwareInterface>
      </joint>
      <actuator name="motor_gripper_body__right_ext">
        <hardwareInterface>hardware_interface/PositionJointInterface</hardwareInterface>
        <mechanicalReduction>1</mechanicalReduction>
      </actuator>
    </transmission>


  <!-- END - Robot description -->

</robot>
